<?xml version="1.0"?>
<robot name="box">

    <!-- Size cyl(0.15,0.8) (Center at 0,0,0) -->
    <link name="base">

        <visual>
            <origin xyz="0 0 0"/>
            <geometry>
                <cylinder radius="0.15" length="0.8"/> 
            </geometry>
            <material name="red">
                <color rgba="1.0 0.0 0.0 1.0"/>
            </material>
                
        </visual>

        <collision>
            <origin xyz="0 0 0"/>
            <geometry>
                <cylinder radius="0.15" length="0.8"/> 
            </geometry>
        </collision>

        <inertial>
            <origin xyz="0 0 0"/>
            <mass value="0.0"/>
            <inertia ixx="0.0" ixy="0.0" ixz="0.0" iyy="0.0" iyz="0.0" izz="0.0"/>
        </inertial>
    </link>

    <!-- Joint [base2stick] -->
    <!-- Parent: base -->
    <!-- New-Center: 0 0 0 (Middle of Stick) -->
    <joint name="base2stick" type="revolute">
        <parent link="base"/>
        <child link="stick"/>
        <origin xyz="0 0 0"/>

        <axis xyz="0.0 0.0 1.0"/>
        <limit lower="0" upper="1.58" effort="100.0" velocity="60.0"/>
    </joint>

    <!-- [Stick] Size 0.1 x 2 x 0.1 -->
    <!-- Parent: base -->
    <!-- Parent-Center: Local(0 0 -0.2) Global(0 0 0) -->
    <!-- Center: Local(0 -0.75 0) -->
    <!-- Gravity Center: Local(0 0 0) -->
    <link name="stick">

        <visual>
            <origin xyz="0 -0.75 0"/>
            <geometry>
                <box size="0.1 2 0.1"/>
            </geometry>
            <material name="red">
                <color rgba="1.0 0.0 0.0 1.0"/>
            </material>
                
        </visual>

        <collision>
            <origin xyz="0 -0.75 0"/>
            <geometry>
                <box size="0.1 2 0.1"/>
            </geometry>
        </collision>

        <inertial>
            <origin xyz="0 0 0"/>
            <mass value="5"/>
            <inertia ixx="0.0" ixy="0.0" ixz="0.0" iyy="0.0" iyz="0.0" izz="0.0"/>
        </inertial>
    </link>

</robot>